[TOC]

## 创建异常
使用 `throw` 关键字创建异常：

```
throw value
```

一旦 JavaScript 执行到此行，则常规的程序流会被停止，且控制会被交给最近的异常处理程序。

通常，在客户端代码中，`value` 可以是任何 JavaScript 值（包括字符传，数字，或对象）。

在 Node.js 中，我们不抛出字符串，而是仅抛出 Error 对象。

## 错误对象
错误对象是 Error 对象的实例、或者继承自 [Error 类](http://nodejs.cn/api/errors.html)：

```
throw new Error('error message')
```

或

```
class NotEnoughCoffeeError extends Error {
  // ...
}
```

## 处理异常
处理异常程序是 `try`/`catch` 语句。

`try` 块中包含的代码行中引发的任何异常都会在相应的 `catch` 块中处理：

```
try {
  // code...
} catch (e) {}
```

可以添加处理程序，它们可以捕获各种错误。

## 捕获未捕获的异常
如果在程序执行过程中引发了未捕获的异常，则程序会崩溃。

若要解决此问题，则监听 `process` 对象上的 `uncaughtException` 事件：

```
process.on('uncaughtException', err => {
  console.error('有一个未捕获的错误', err)
  process.exit(1) // 强制性的
})
```

无需为此导入 `process` 核心模块，因为它是自动注入的。

## Promise 的异常
使用 promise 可以链接不同的操作，并在最后处理错误：

```
doSth1()
  .then(doSth2)
  .then(doSth3)
  .catch(err => console.error(err))
```

你怎么直到错误发生在那里？你并不知道，但是你可以处理所调用的每个函数（doSthX）中的错误，并且在错误处理程序内部抛出新的错误，这就会调用外部的 `catch` 处理程序:

```
const doSth1 = () => {
  // ...
  try {
    // ...
  } catch (err) {
    // ... 在本地处理
    throw new Error(err.message)
  }
  // ...
}
```

为了能够在本地（而不是在调用的函数中）处理错误，则可以断开链条，在每个 `then()` 函数中创建函数并处理异常：

```
doSth1()
  .then(() => {
    return doSth2().catch(err => {
      // 处理错误
      throw err // 打断链条
    })
  })
  .then(() => {
    return doSth2().catch(err => {
      // 处理错误
      throw err // 打断链条
    })
  })
  .catch(err => console.error(err))
```

## async/await 的错误处理
使用 async/await 时，仍然需要捕获错误，可以通过以下方式进行操作：

```
async function someFunc() {
  try {
    await someFunc()
  } catch (err) {
     console.err(err.message)
  }
}
```